Watching for file changes with StatReloader
Exception in thread django-main-thread:
Traceback (most recent call last):
  File "C:\Users\Arendt\AppData\Local\Programs\Python\Python310\lib\threading.py", line 1016, in _bootstrap_inner
    self.run()
  File "C:\Users\Arendt\AppData\Local\Programs\Python\Python310\lib\threading.py", line 953, in run
    self._target(*self._args, **self._kwargs)
  File "C:\Users\Arendt\AppData\Local\Programs\Python\Python310\lib\site-packages\django\utils\autoreload.py", line 64, in wrapper
    fn(*args, **kwargs)
  File "C:\Users\Arendt\AppData\Local\Programs\Python\Python310\lib\site-packages\django\core\management\commands\runserver.py", line 134, in inner_run
    self.check(display_num_errors=True)
  File "C:\Users\Arendt\AppData\Local\Programs\Python\Python310\lib\site-packages\django\core\management\base.py", line 486, in check
    all_issues = checks.run_checks(
  File "C:\Users\Arendt\AppData\Local\Programs\Python\Python310\lib\site-packages\django\core\checks\registry.py", line 88, in run_checks
    new_errors = check(app_configs=app_configs, databases=databases)
  File "C:\Users\Arendt\AppData\Local\Programs\Python\Python310\lib\site-packages\django\core\checks\urls.py", line 136, in check_custom_error_handlers
    handler = resolver.resolve_error_handler(status_code)
  File "C:\Users\Arendt\AppData\Local\Programs\Python\Python310\lib\site-packages\django\urls\resolvers.py", line 732, in resolve_error_handler
    callback = getattr(self.urlconf_module, "handler%s" % view_type, None)
  File "C:\Users\Arendt\AppData\Local\Programs\Python\Python310\lib\site-packages\django\utils\functional.py", line 47, in __get__
    res = instance.__dict__[self.name] = self.func(instance)
  File "C:\Users\Arendt\AppData\Local\Programs\Python\Python310\lib\site-packages\django\urls\resolvers.py", line 711, in urlconf_module
    return import_module(self.urlconf_name)
  File "C:\Users\Arendt\AppData\Local\Programs\Python\Python310\lib\importlib\__init__.py", line 126, in import_module
    return _bootstrap._gcd_import(name[level:], package, level)
  File "<frozen importlib._bootstrap>", line 1050, in _gcd_import
  File "<frozen importlib._bootstrap>", line 1027, in _find_and_load
  File "<frozen importlib._bootstrap>", line 1006, in _find_and_load_unlocked
  File "<frozen importlib._bootstrap>", line 688, in _load_unlocked
  File "<frozen importlib._bootstrap_external>", line 883, in exec_module
  File "<frozen importlib._bootstrap>", line 241, in _call_with_frames_removed
  File "C:\Users\Arendt\Desktop\WorkBy\freelance_platform\freelance_core\urls.py", line 51, in <module>
    path('chat/', include('chat.urls')),
  File "C:\Users\Arendt\AppData\Local\Programs\Python\Python310\lib\site-packages\django\urls\conf.py", line 39, in include
    urlconf_module = import_module(urlconf_module)
  File "C:\Users\Arendt\AppData\Local\Programs\Python\Python310\lib\importlib\__init__.py", line 126, in import_module
    return _bootstrap._gcd_import(name[level:], package, level)
  File "<frozen importlib._bootstrap>", line 1050, in _gcd_import
  File "<frozen importlib._bootstrap>", line 1027, in _find_and_load
  File "<frozen importlib._bootstrap>", line 1006, in _find_and_load_unlocked
  File "<frozen importlib._bootstrap>", line 688, in _load_unlocked
  File "<frozen importlib._bootstrap_external>", line 883, in exec_module
  File "<frozen importlib._bootstrap>", line 241, in _call_with_frames_removed
  File "C:\Users\Arendt\Desktop\WorkBy\freelance_platform\chat\urls.py", line 14, in <module>
    path('api/send_message/<int:pk>/', views.api_send_message, name='api_send_message'),
AttributeError: module 'chat.views' has no attribute 'api_send_message'. Did you mean: 'api_send_message_view'?
C:\Users\Arendt\Desktop\WorkBy\freelance_platform\chat\urls.py changed, reloading.
Performing system checks...

Watching for file changes with StatReloader
Exception in thread django-main-thread:
Traceback (most recent call last):
  File "C:\Users\Arendt\AppData\Local\Programs\Python\Python310\lib\threading.py", line 1016, in _bootstrap_inner
    self.run()
  File "C:\Users\Arendt\AppData\Local\Programs\Python\Python310\lib\threading.py", line 953, in run
    self._target(*self._args, **self._kwargs)
  File "C:\Users\Arendt\AppData\Local\Programs\Python\Python310\lib\site-packages\django\utils\autoreload.py", line 64, in wrapper
    fn(*args, **kwargs)
  File "C:\Users\Arendt\AppData\Local\Programs\Python\Python310\lib\site-packages\django\core\management\commands\runserver.py", line 134, in inner_run
    self.check(display_num_errors=True)
  File "C:\Users\Arendt\AppData\Local\Programs\Python\Python310\lib\site-packages\django\core\management\base.py", line 486, in check
    all_issues = checks.run_checks(
  File "C:\Users\Arendt\AppData\Local\Programs\Python\Python310\lib\site-packages\django\core\checks\registry.py", line 88, in run_checks
    new_errors = check(app_configs=app_configs, databases=databases)
  File "C:\Users\Arendt\AppData\Local\Programs\Python\Python310\lib\site-packages\django\core\checks\urls.py", line 136, in check_custom_error_handlers
    handler = resolver.resolve_error_handler(status_code)
  File "C:\Users\Arendt\AppData\Local\Programs\Python\Python310\lib\site-packages\django\urls\resolvers.py", line 732, in resolve_error_handler
    callback = getattr(self.urlconf_module, "handler%s" % view_type, None)
  File "C:\Users\Arendt\AppData\Local\Programs\Python\Python310\lib\site-packages\django\utils\functional.py", line 47, in __get__
    res = instance.__dict__[self.name] = self.func(instance)
  File "C:\Users\Arendt\AppData\Local\Programs\Python\Python310\lib\site-packages\django\urls\resolvers.py", line 711, in urlconf_module
    return import_module(self.urlconf_name)
  File "C:\Users\Arendt\AppData\Local\Programs\Python\Python310\lib\importlib\__init__.py", line 126, in import_module
    return _bootstrap._gcd_import(name[level:], package, level)
  File "<frozen importlib._bootstrap>", line 1050, in _gcd_import
  File "<frozen importlib._bootstrap>", line 1027, in _find_and_load
  File "<frozen importlib._bootstrap>", line 1006, in _find_and_load_unlocked
  File "<frozen importlib._bootstrap>", line 688, in _load_unlocked
  File "<frozen importlib._bootstrap_external>", line 883, in exec_module
  File "<frozen importlib._bootstrap>", line 241, in _call_with_frames_removed
  File "C:\Users\Arendt\Desktop\WorkBy\freelance_platform\freelance_core\urls.py", line 51, in <module>
    path('chat/', include('chat.urls')),
  File "C:\Users\Arendt\AppData\Local\Programs\Python\Python310\lib\site-packages\django\urls\conf.py", line 39, in include
    urlconf_module = import_module(urlconf_module)
  File "C:\Users\Arendt\AppData\Local\Programs\Python\Python310\lib\importlib\__init__.py", line 126, in import_module
    return _bootstrap._gcd_import(name[level:], package, level)
  File "<frozen importlib._bootstrap>", line 1050, in _gcd_import
  File "<frozen importlib._bootstrap>", line 1027, in _find_and_load
  File "<frozen importlib._bootstrap>", line 1006, in _find_and_load_unlocked
  File "<frozen importlib._bootstrap>", line 688, in _load_unlocked
  File "<frozen importlib._bootstrap_external>", line 883, in exec_module
  File "<frozen importlib._bootstrap>", line 241, in _call_with_frames_removed
  File "C:\Users\Arendt\Desktop\WorkBy\freelance_platform\chat\urls.py", line 17, in <module>
    path('api/conversations/', views.api_get_conversations, name='api_get_conversations'),
AttributeError: module 'chat.views' has no attribute 'api_get_conversations'
C:\Users\Arendt\Desktop\WorkBy\freelance_platform\chat\urls.py changed, reloading.
Performing system checks...

Watching for file changes with StatReloader
Exception in thread django-main-thread:
Traceback (most recent call last):
  File "C:\Users\Arendt\AppData\Local\Programs\Python\Python310\lib\threading.py", line 1016, in _bootstrap_inner
    self.run()
  File "C:\Users\Arendt\AppData\Local\Programs\Python\Python310\lib\threading.py", line 953, in run
    self._target(*self._args, **self._kwargs)
  File "C:\Users\Arendt\AppData\Local\Programs\Python\Python310\lib\site-packages\django\utils\autoreload.py", line 64, in wrapper
    fn(*args, **kwargs)
  File "C:\Users\Arendt\AppData\Local\Programs\Python\Python310\lib\site-packages\django\core\management\commands\runserver.py", line 134, in inner_run
    self.check(display_num_errors=True)
  File "C:\Users\Arendt\AppData\Local\Programs\Python\Python310\lib\site-packages\django\core\management\base.py", line 486, in check
    all_issues = checks.run_checks(
  File "C:\Users\Arendt\AppData\Local\Programs\Python\Python310\lib\site-packages\django\core\checks\registry.py", line 88, in run_checks
    new_errors = check(app_configs=app_configs, databases=databases)
  File "C:\Users\Arendt\AppData\Local\Programs\Python\Python310\lib\site-packages\django\core\checks\urls.py", line 136, in check_custom_error_handlers
    handler = resolver.resolve_error_handler(status_code)
  File "C:\Users\Arendt\AppData\Local\Programs\Python\Python310\lib\site-packages\django\urls\resolvers.py", line 732, in resolve_error_handler
    callback = getattr(self.urlconf_module, "handler%s" % view_type, None)
  File "C:\Users\Arendt\AppData\Local\Programs\Python\Python310\lib\site-packages\django\utils\functional.py", line 47, in __get__
    res = instance.__dict__[self.name] = self.func(instance)
  File "C:\Users\Arendt\AppData\Local\Programs\Python\Python310\lib\site-packages\django\urls\resolvers.py", line 711, in urlconf_module
    return import_module(self.urlconf_name)
  File "C:\Users\Arendt\AppData\Local\Programs\Python\Python310\lib\importlib\__init__.py", line 126, in import_module
    return _bootstrap._gcd_import(name[level:], package, level)
  File "<frozen importlib._bootstrap>", line 1050, in _gcd_import
  File "<frozen importlib._bootstrap>", line 1027, in _find_and_load
  File "<frozen importlib._bootstrap>", line 1006, in _find_and_load_unlocked
  File "<frozen importlib._bootstrap>", line 688, in _load_unlocked
  File "<frozen importlib._bootstrap_external>", line 883, in exec_module
  File "<frozen importlib._bootstrap>", line 241, in _call_with_frames_removed
  File "C:\Users\Arendt\Desktop\WorkBy\freelance_platform\freelance_core\urls.py", line 51, in <module>
    path('chat/', include('chat.urls')),
  File "C:\Users\Arendt\AppData\Local\Programs\Python\Python310\lib\site-packages\django\urls\conf.py", line 39, in include
    urlconf_module = import_module(urlconf_module)
  File "C:\Users\Arendt\AppData\Local\Programs\Python\Python310\lib\importlib\__init__.py", line 126, in import_module
    return _bootstrap._gcd_import(name[level:], package, level)
  File "<frozen importlib._bootstrap>", line 1050, in _gcd_import
  File "<frozen importlib._bootstrap>", line 1027, in _find_and_load
  File "<frozen importlib._bootstrap>", line 1006, in _find_and_load_unlocked
  File "<frozen importlib._bootstrap>", line 688, in _load_unlocked
  File "<frozen importlib._bootstrap_external>", line 883, in exec_module
  File "<frozen importlib._bootstrap>", line 241, in _call_with_frames_removed
  File "C:\Users\Arendt\Desktop\WorkBy\freelance_platform\chat\urls.py", line 19, in <module>
    path('api/mark_notification_read/<int:pk>/', views.api_mark_notification_read_view, name='api_mark_notification_read'),
AttributeError: module 'chat.views' has no attribute 'api_mark_notification_read_view'. Did you mean: 'mark_notification_read_view'?
C:\Users\Arendt\Desktop\WorkBy\freelance_platform\jobs\models.py changed, reloading.
Performing system checks...

Watching for file changes with StatReloader
Exception in thread django-main-thread:
Traceback (most recent call last):
  File "C:\Users\Arendt\AppData\Local\Programs\Python\Python310\lib\threading.py", line 1016, in _bootstrap_inner
    self.run()
  File "C:\Users\Arendt\AppData\Local\Programs\Python\Python310\lib\threading.py", line 953, in run
    self._target(*self._args, **self._kwargs)
  File "C:\Users\Arendt\AppData\Local\Programs\Python\Python310\lib\site-packages\django\utils\autoreload.py", line 64, in wrapper
    fn(*args, **kwargs)
  File "C:\Users\Arendt\AppData\Local\Programs\Python\Python310\lib\site-packages\django\core\management\commands\runserver.py", line 134, in inner_run
    self.check(display_num_errors=True)
  File "C:\Users\Arendt\AppData\Local\Programs\Python\Python310\lib\site-packages\django\core\management\base.py", line 486, in check
    all_issues = checks.run_checks(
  File "C:\Users\Arendt\AppData\Local\Programs\Python\Python310\lib\site-packages\django\core\checks\registry.py", line 88, in run_checks
    new_errors = check(app_configs=app_configs, databases=databases)
  File "C:\Users\Arendt\AppData\Local\Programs\Python\Python310\lib\site-packages\django\core\checks\urls.py", line 136, in check_custom_error_handlers
    handler = resolver.resolve_error_handler(status_code)
  File "C:\Users\Arendt\AppData\Local\Programs\Python\Python310\lib\site-packages\django\urls\resolvers.py", line 732, in resolve_error_handler
    callback = getattr(self.urlconf_module, "handler%s" % view_type, None)
  File "C:\Users\Arendt\AppData\Local\Programs\Python\Python310\lib\site-packages\django\utils\functional.py", line 47, in __get__
    res = instance.__dict__[self.name] = self.func(instance)
  File "C:\Users\Arendt\AppData\Local\Programs\Python\Python310\lib\site-packages\django\urls\resolvers.py", line 711, in urlconf_module
    return import_module(self.urlconf_name)
  File "C:\Users\Arendt\AppData\Local\Programs\Python\Python310\lib\importlib\__init__.py", line 126, in import_module
    return _bootstrap._gcd_import(name[level:], package, level)
  File "<frozen importlib._bootstrap>", line 1050, in _gcd_import
  File "<frozen importlib._bootstrap>", line 1027, in _find_and_load
  File "<frozen importlib._bootstrap>", line 1006, in _find_and_load_unlocked
  File "<frozen importlib._bootstrap>", line 688, in _load_unlocked
  File "<frozen importlib._bootstrap_external>", line 883, in exec_module
  File "<frozen importlib._bootstrap>", line 241, in _call_with_frames_removed
  File "C:\Users\Arendt\Desktop\WorkBy\freelance_platform\freelance_core\urls.py", line 51, in <module>
    path('chat/', include('chat.urls')),
  File "C:\Users\Arendt\AppData\Local\Programs\Python\Python310\lib\site-packages\django\urls\conf.py", line 39, in include
    urlconf_module = import_module(urlconf_module)
  File "C:\Users\Arendt\AppData\Local\Programs\Python\Python310\lib\importlib\__init__.py", line 126, in import_module
    return _bootstrap._gcd_import(name[level:], package, level)
  File "<frozen importlib._bootstrap>", line 1050, in _gcd_import
  File "<frozen importlib._bootstrap>", line 1027, in _find_and_load
  File "<frozen importlib._bootstrap>", line 1006, in _find_and_load_unlocked
  File "<frozen importlib._bootstrap>", line 688, in _load_unlocked
  File "<frozen importlib._bootstrap_external>", line 883, in exec_module
  File "<frozen importlib._bootstrap>", line 241, in _call_with_frames_removed
  File "C:\Users\Arendt\Desktop\WorkBy\freelance_platform\chat\urls.py", line 19, in <module>
    path('api/mark_notification_read/<int:pk>/', views.api_mark_notification_read_view, name='api_mark_notification_read'),
AttributeError: module 'chat.views' has no attribute 'api_mark_notification_read_view'. Did you mean: 'mark_notification_read_view'?
C:\Users\Arendt\Desktop\WorkBy\freelance_platform\chat\urls.py changed, reloading.
Performing system checks...

Watching for file changes with StatReloader
System check identified some issues:

WARNINGS:
<django.template.backends.django.DjangoTemplates object at 0x000001ABD7A84430>: (templates.W003) 'form_tags' is used for multiple template tag modules: 'accounts.templatetags.form_tags', 'jobs.templatetags.form_tags'

System check identified 1 issue (0 silenced).
